Workbook

Sheet Week of 46-410
B1: CW | C1: Fortune | D1: Viola | E1: A1 Firewood | F1: Wabash | G1: Superior | H1: Aya | I1: Closed Loop | J1: Testa | K1: Cornille | L1: Rare Tea Cellar | M1: Steve's | N1: Turano | O1: Daily Spend | P1: Daily Revenue | Q1: Daily Cost %
A2: Wednesday | B2: 5570.11 | C2: 1407.23 | D2: 446.88 | E2: 390 | I2: 242 | M2: 100 | O2: =SUM(B2:N2) -> 8156.22 | P2: 7462 | Q2: =O2/P2 -> 1.093034
A3: Thursday | B3: 2108.57 | C3: 261.09 | K3: 800 | O3: =SUM(B3:N3) -> 3169.66 | P3: 6777.8 | Q3: =O3/P3 -> 0.46765322
A4: Friday | B4: 1452.79 | C4: 266.5 | G4: 355 | H4: 127.3 | J4: 370.5 | L4: 52 | M4: 100 | N4: 277.41 | O4: =SUM(B4:N4) -> 3001.5 | P4: 9749 | Q4: =O4/P4 -> 0.30787773
A5: Saturday | B5: 1533.03 | C5: 928.1 | O5: =SUM(B5:N5) -> 2461.13 | P5: =3555+10500.8 -> 14055.8 | Q5: =O5/P5 -> 0.17509711
A6: Sunday | B6: N/A | C6: N/A | D6: N/A | E6: N/A | G6: N/A | H6: 45.6 | I6: N/A | J6: N/A | K6: N/A | L6: N/A | M6: N/A | N6: N/A | O6: 0 | P6: 9949 | Q6: =O6/P6 -> 0
A9: Budget | B9: 14000
A10: Total Weekly Spend | B10: =SUM(B2:N6) -> 16834.11
A11: Remaing Spend | B11: =SUM(B9-B10) -> -2834.11
A13: Weekly Food Revenue | B13: =SUM(P2:P6) -> 47993.6
A14: Weekly Cost % | B14: =B10/B13 -> 0.35075739
A17: End of week status
A18: list items over $100
A19: Items carrying over | B19: Amount | C19: Items discarded | D19: Amount
A23: Duck week 1
A25: Duck Week 2
A27: Duck Week 3
A32: Total | B32: =sum(B20:B31) -> 0 | D32: =sum(D20:D31) -> 0

Sheet Week of 413-417
B1: CW | C1: Fortune | D1: Viola | E1: A1 Firewood | F1: Superior | G1: Aya | H1: Closed Loop | I1: Truffles/ carryover | J1: Cornille | K1: Rare Tea Cellar | L1: Steve's | M1: Turano | N1: Daily Spend | O1: Daily Revenue | P1: Daily Cost %
A2: Wednesday | B2: 5315.67 | C2: 754.4 | E2: 390 | F2: 177.5 | H2: 242 | I2: 500 | K2: 46.5 | L2: 100 | N2: =SUM(B2:M2) -> 7526.07 | O2: 7831.47 | P2: =N2/O2 -> 0.96100349
A3: Thursday | B3: 1600.5 | C3: 90.4 | D3: 446.88 | J3: 450 | N3: =SUM(B3:M3) -> 2587.78 | O3: 8512.1 | P3: =N3/O3 -> 0.30401194
A4: Friday | B4: 1278.77 | C4: 473.8 | G4: 127.3 | I4: 370.5 | L4: 100 | M4: 277.41 | N4: =SUM(B4:M4) -> 2627.78 | O4: 10478 | P4: =N4/O4 -> 0.25079023
A5: Saturday | B5: 1675.34 | C5: 310.4 | K5: 19 | N5: =SUM(B5:M5) -> 2004.74 | O5: 13260 | P5: =N5/O5 -> 0.15118703
A6: Sunday | B6: N/A | C6: N/A | D6: N/A | E6: N/A | F6: N/A | G6: N/A | H6: N/A | I6: N/A | J6: N/A | K6: N/A | L6: N/A | M6: N/A | N6: 0 | O6: 10550 | P6: =N6/O6 -> 0
A9: Budget | B9: 14000
A10: Total Weekly Spend | B10: =SUM(B2:M6) -> 14746.37
A11: Remaing Spend | B11: =SUM(B9-B10) -> -746.37
A13: Weekly Food Revenue | B13: =SUM(O2:O6) -> 50631.57
A14: Weekly Cost % | B14: =B10/B13 -> 0.29124852
A17: End of week status
A18: list items over $100
A19: Items carrying over | B19: Amount | C19: Items discarded | D19: Amount
A32: Total | B32: =sum(B20:B31) -> 0 | D32: =sum(D20:D31) -> 0

Sheet (Roister)Week of 420- 424
B1: CW | C1: Fortune | D1: Viola | E1: A1 Firewood | F1: Superior | G1: Aya | H1: Closed Loop | I1: Truffles/ carryover | J1: Cornille | K1: Rare Tea Cellar | L1: Steve's | M1: Turano | N1: Daily Spend | O1: Daily Revenue | P1: Daily Cost %
A2: Wednesday | B2: 4808.69 | C2: 1633.2 | E2: 390 | H2: 242 | I2: 370.5 | K2: 52 | L2: 100 | N2: =SUM(B2:M2) -> 7596.39 | O2: 7097 | P2: =N2/O2 -> 1.0703664
A3: Thursday | B3: 1152.18 | C3: 138.7 | D3: 446.88 | J3: 400 | N3: =SUM(B3:M3) -> 2137.76 | O3: 6330 | P3: =N3/O3 -> 0.3377188
A4: Friday | B4: 2399.9 | C4: 491.48 | G4: 127.3 | L4: 100 | M4: 277.41 | N4: =SUM(B4:M4) -> 3396.09 | P4: =N4/O4 -> #DIV/0!
A5: Saturday | B5: 1551.56 | C5: 402.25 | I5: 370.5 | N5: =SUM(B5:M5) -> 2324.31 | O5: 16070.01 | P5: =N5/O5 -> 0.1446365
A6: Sunday | B6: N/A | C6: N/A | D6: N/A | E6: N/A | F6: N/A | G6: N/A | H6: N/A | I6: N/A | J6: N/A | K6: N/A | L6: N/A | M6: N/A | N6: 0 | O6: 13009.5 | P6: =N6/O6 -> 0
A9: Budget | B9: 14000
A10: Total Weekly Spend | B10: =SUM(B2:M6) -> 15454.55
A11: Remaing Spend | B11: =SUM(B9-B10) -> -1454.55
A13: Weekly Food Revenue | B13: =SUM(O2:O6) -> 42506.51
A14: Weekly Cost % | B14: =B10/B13 -> 0.36358078
A17: End of week status
A18: list items over $100
A19: Items carrying over | B19: Amount | C19: Items discarded | D19: Amount
A32: Total | B32: =sum(B20:B31) -> 0 | D32: =sum(D20:D31) -> 0

Sheet (Roister) Week of 54- 58
B1: CW | C1: Fortune | D1: Viola | E1: A1 Firewood | F1: Superior | G1: Aya | H1: Closed Loop | I1: Truffles/ carryover | J1: Cornille | K1: Rare Tea Cellar | L1: Steve's | M1: Turano | N1: Daily Spend | O1: Daily Revenue | P1: Daily Cost %
A2: Wednesday | B2: 4940.53 | C2: 1684.15 | E2: 390 | F2: 355 | H2: 242 | K2: 39 | L2: 100 | N2: =SUM(B2:M2) -> 7750.68 | O2: 7362 | P2: =N2/O2 -> 1.0527954
A3: Thursday | B3: 1751.9 | C3: 269 | D3: 446.88 | J3: 350 | N3: =SUM(B3:M3) -> 2817.78 | O3: 10200.96 | P3: =N3/O3 -> 0.27622694
A4: Friday | B4: 1650.04 | C4: 593.85 | G4: 127.3 | L4: 100 | M4: 277.41 | N4: =SUM(B4:M4) -> 2748.6 | O4: 11475.8 | P4: =N4/O4 -> 0.23951271
A5: Saturday | B5: 2131.75 | C5: 200.3 | F5: 245.64 | G5: 76 | N5: =SUM(B5:M5) -> 2653.69 | O5: 17111.5 | P5: =N5/O5 -> 0.15508225
A6: Sunday | B6: N/A | C6: N/A | D6: N/A | E6: N/A | F6: N/A | G6: N/A | H6: N/A | I6: N/A | J6: N/A | K6: N/A | L6: N/A | M6: N/A | N6: 0 | O6: 12811 | P6: =N6/O6 -> 0
A9: Budget | B9: 14000
A10: Total Weekly Spend | B10: =SUM(B2:M6) -> 15970.75
A11: Remaing Spend | B11: =SUM(B9-B10) -> -1970.75
A13: Weekly Food Revenue | B13: =SUM(O2:O6) -> 58961.26
A14: Weekly Cost % | B14: =B10/B13 -> 0.27086853
A17: End of week status
A18: list items over $100
A19: Items carrying over | B19: Amount | C19: Items discarded | D19: Amount
A32: Total | B32: =sum(B20:B31) -> 0 | D32: =sum(D20:D31) -> 0

Sheet (Roister) Week of 427-51
B1: CW | C1: Fortune | D1: Viola | E1: A1 Firewood | F1: Superior | G1: Aya | H1: Closed Loop | I1: Truffles/ carryover | J1: Cornille | K1: Rare Tea Cellar | L1: Steve's | M1: Turano | N1: Daily Spend | O1: Daily Revenue | P1: Daily Cost %
A2: Wednesday | B2: 5588.35 | C2: 1525 | E2: 390 | F2: 248.95 | H2: 242 | K2: 15.95 | L2: 100 | N2: =SUM(B2:M2) -> 8110.25 | O2: 7023.01 | P2: =N2/O2 -> 1.1548111
A3: Thursday | B3: 2447.87 | C3: 243.93 | D3: 446.88 | I3: 370.15 | N3: =SUM(B3:M3) -> 3508.83 | O3: 8057 | P3: =N3/O3 -> 0.43550081
A4: Friday | B4: 2193.28 | C4: 234.15 | G4: 127.3 | L4: 100 | M4: 277.41 | N4: =SUM(B4:M4) -> 2932.14 | O4: 10393.4 | P4: =N4/O4 -> 0.28211557
A5: Saturday | B5: 2361.93 | C5: 146.8 | I5: 370.15 | K5: 25 | N5: =SUM(B5:M5) -> 2903.88 | O5: 14361 | P5: =N5/O5 -> 0.20220597
A6: Sunday | B6: N/A | C6: N/A | D6: N/A | E6: N/A | F6: N/A | G6: N/A | H6: N/A | I6: N/A | J6: N/A | K6: N/A | L6: N/A | M6: N/A | N6: 0 | O6: 11288.6 | P6: =N6/O6 -> 0
A9: Budget | B9: 14000
A10: Total Weekly Spend | B10: =SUM(B2:M6) -> 17455.1
A11: Remaing Spend | B11: =SUM(B9-B10) -> -3455.1
A13: Weekly Food Revenue | B13: =SUM(O2:O6) -> 51123.01
A14: Weekly Cost % | B14: =B10/B13 -> 0.34143334
A17: End of week status
A18: list items over $100
A19: Items carrying over | B19: Amount | C19: Items discarded | D19: Amount
A32: Total | B32: =sum(B20:B31) -> 0 | D32: =sum(D20:D31) -> 0

Sheet Roister Week of 519- 523
B1: CW | C1: Fortune | D1: Viola | E1: A1 Firewood | F1: Superior | G1: Aya | H1: Closed Loop | I1: Truffles/ carryover | J1: Cornille | K1: Rare Tea Cellar | L1: Steve's | M1: Turano | N1: Daily Spend | O1: Daily Revenue | P1: Daily Cost %
A2: Wednesday | B2: 3552.49 | C2: 309.3 | E2: 390 | F2: 355 | H2: 242 | I2: 440 | L2: 100 | N2: =SUM(B2:M2) -> 5388.79 | O2: 0 | P2: =N2/O2 -> #DIV/0!
A3: Thursday | B3: 871.14 | C3: 532.96 | D3: 446.88 | N3: =SUM(B3:M3) -> 1850.98 | O3: 17208.75 | P3: =N3/O3 -> 0.1075604
A4: Friday | B4: 2065.2 | C4: 466.8 | G4: 127.3 | J4: 800 | K4: 44.5 | L4: 100 | M4: 277.41 | N4: =SUM(B4:M4) -> 3881.21 | O4: 13514 | P4: =N4/O4 -> 0.2871992
A5: Saturday | B5: 2482.46 | C5: 1042.79 | N5: =SUM(B5:M5) -> 3525.25 | O5: 20288.1 | P5: =N5/O5 -> 0.17375949
A6: Sunday | B6: N/A | C6: N/A | D6: N/A | E6: N/A | F6: N/A | G6: N/A | H6: N/A | I6: N/A | J6: N/A | K6: N/A | L6: N/A | M6: N/A | N6: 0 | O6: 20679 | P6: =N6/O6 -> 0
A9: Budget | B9: 14000
A10: Total Weekly Spend | B10: =SUM(B2:M6) -> 14646.23
A11: Remaing Spend | B11: =SUM(B9-B10) -> -646.23
A13: Weekly Food Revenue | B13: =SUM(O2:O6) -> 71689.85
A14: Weekly Cost % | B14: =B10/B13 -> 0.20429991

Sheet Roister (511-515)
B1: CW | C1: Fortune | D1: Viola | E1: A1 Firewood | F1: Superior | G1: Aya | H1: Closed Loop | I1: Truffles/ carryover | J1: Cornille | K1: Rare Tea Cellar | L1: Steve's | M1: Turano | N1: Daily Spend | O1: Daily Revenue | P1: Daily Cost %
A2: Wednesday | B2: 3196.04 | C2: 284.63 | E2: 390 | H2: 242 | K2: 183.45 | L2: 100 | N2: =SUM(B2:M2) -> 4396.12 | O2: 8400.5 | P2: =N2/O2 -> 0.52331647
A3: Thursday | B3: 1692.44 | C3: 550.86 | D3: 446.88 | J3: 350 | N3: =SUM(B3:M3) -> 3040.18 | O3: 10570.5 | P3: =N3/O3 -> 0.28760986
A4: Friday | B4: 1448.71 | C4: 185 | I4: 1000 | N4: =SUM(B4:M4) -> 2633.71 | O4: 15153 | P4: =N4/O4 -> 0.17380783
A5: Saturday | N5: =SUM(B5:M5) -> 0 | P5: =N5/O5 -> #DIV/0!
A6: Sunday | B6: N/A | C6: N/A | D6: N/A | E6: N/A | F6: N/A | G6: N/A | H6: N/A | I6: N/A | J6: N/A | K6: N/A | L6: N/A | M6: N/A | N6: 0 | P6: =N6/O6 -> #DIV/0!
A9: Budget | B9: 14000
A10: Total Weekly Spend | B10: =SUM(B2:M6) -> 10070.01
A11: Remaing Spend | B11: =SUM(B9-B10) -> 3929.99
A13: Weekly Food Revenue | B13: =SUM(O2:O6) -> 34124
A14: Weekly Cost % | B14: =B10/B13 -> 0.29510052
A17: End of week status
A18: list items over $100
A19: Items carrying over | B19: Amount | C19: Items discarded | D19: Amount
A32: Total | B32: =sum(B20:B31) -> 0 | D32: =sum(D20:D31) -> 0

Sheet Week of 525-529
B1: CW | C1: Fortune | D1: Viola | E1: A1 Firewood | F1: Superior | G1: Aya | H1: Closed Loop | I1: Truffles | J1: Cornille | K1: Rare Tea Cellar | L1: Steve's | M1: Turano | N1: Daily Spend | O1: Daily Revenue | P1: Daily Cost %
A2: Monday | B2: 2653.7 | C2: 1042.79 | I2: 440 | K2: 49.5 | N2: =SUM(B2:M2) -> 4185.99 | O2: 13711 | P2: =N2/O2 -> 0.30530158
A3: Wednesday | B3: 5982.13 | C3: 1314.46 | D3: 446.88 | E3: 390 | H3: 242 | K3: 168 | L3: 100 | N3: =SUM(B3:M3) -> 8643.47 | O3: 8168.6 | P3: =N3/O3 -> 1.0581336
A4: Thursday | B4: 3616.3 | C4: 1053.03 | N4: =SUM(B4:M4) -> 4669.33 | O4: 9119.2 | P4: =N4/O4 -> 0.51203285
A5: Friday | B5: 1049.5 | C5: 722.07 | F5: 248.5 | G5: 127.3 | L5: 100 | M5: 277.41 | N5: =SUM(B5:M5) -> 2524.78 | O5: 13446 | P5: =N5/O5 -> 0.18777183
A6: Saturday | B6: 2983.87 | C6: 722.07 | G6: 45.6 | K6: 44.5 | N6: =SUM(C6:M6) -> 812.17 | O6: 20810 | P6: =N6/O6 -> 0.039027871
A7: Sunday | B7: N/A | C7: N/A | D7: N/A | E7: N/A | F7: N/A | G7: N/A | H7: N/A | I7: N/A | J7: N/A | K7: N/A | L7: N/A | M7: N/A | N7: 0 | O7: 19021.53 | P7: =N7/O7 -> 0
A9: Budget | B9: 14000
A10: Total Weekly Spend | B10: =SUM(B3:M7) -> 19633.62
A11: Remaing Spend | B11: =SUM(B9-B10) -> -5633.62 | I11: 6 ribeyes
A13: Weekly Food Revenue | B13: =SUM(O2:O7) -> 84276.33
A14: Weekly Cost % | B14: =B10/B13 -> 0.23296719

Sheet Roister week of (61-65)
B1: CW | C1: Fortune | D1: Viola | E1: A1 Firewood | F1: Superior | G1: Aya | H1: Closed Loop | I1: Truffles/ carryover | J1: Cornille | K1: Rare Tea Cellar | L1: Steve's | M1: Turano | N1: Daily Spend | O1: Daily Revenue | P1: Daily Cost %
A2: Wednesday | B2: 4777.09 | C2: 725.25 | E2: 390 | F2: 355 | H2: 242 | K2: 67.5 | L2: 100 | N2: =SUM(B2:M2) -> 6656.84 | O2: 8581 | P2: =N2/O2 -> 0.77576506
A3: Thursday | B3: 2135.6 | C3: 368.04 | D3: 510.72 | I3: 440 | J3: 750 | N3: =SUM(B3:M3) -> 4204.36 | O3: 0 | P3: =N3/O3 -> #DIV/0!
A4: Friday | B4: 1113.2 | C4: 444.81 | G4: 127.3 | L4: 100 | M4: 277.41 | N4: =SUM(B4:M4) -> 2062.72 | O4: 15905.6 | P4: =N4/O4 -> 0.12968514
A5: Saturday | B5: 1834.33 | C5: 485.4 | N5: =SUM(B5:M5) -> 2319.73 | O5: =3947+16083 -> 20030 | P5: =N5/O5 -> 0.11581278
A6: Sunday | B6: N/A | C6: N/A | D6: N/A | E6: N/A | F6: N/A | G6: N/A | H6: N/A | I6: N/A | J6: N/A | K6: N/A | L6: N/A | M6: N/A | N6: 0 | O6: 13700.2 | P6: =N6/O6 -> 0
A9: Budget | B9: 14000
A10: Total Weekly Spend | B10: =SUM(B2:M6) -> 15243.65
A11: Remaing Spend | B11: =SUM(B9-B10) -> -1243.65
A13: Weekly Food Revenue | B13: =SUM(O2:O6) -> 58216.8
A14: Weekly Cost % | B14: =B10/B13 -> 0.2618428

Sheet Roister week of (68-612)
B1: CW | C1: Fortune | D1: Viola | E1: A1 Firewood | F1: Superior | G1: Aya | H1: Closed Loop | I1: D'artagnan | J1: Cornille | K1: Rare Tea Cellar | L1: Steve's | M1: Turano | N1: Daily Spend | O1: Daily Revenue | P1: Daily Cost %
A2: Wednesday | B2: 5671.82 | C2: 698.37 | D2: 510.72 | E2: 390 | F2: 783.75 | H2: 242 | I2: 3662.58 | K2: 68 | L2: 100 | N2: =SUM(B2:M2) -> 12127.24 | O2: 13068 | P2: =N2/O2 -> 0.92801041
A3: Thursday | B3: 1982.7 | C3: 723.65 | N3: =SUM(B3:M3) -> 2706.35 | O3: 12027 | P3: =N3/O3 -> 0.22502287
A4: Friday | B4: 2547.85 | C4: 996.64 | G4: 127.3 | I4: 1836.89 | L4: 100 | M4: 277.41 | N4: =SUM(B4:M4) -> 5886.09 | O4: 13246.6 | P4: =N4/O4 -> 0.44434723
A5: Saturday | B5: 2786.88 | C5: 928.1 | N5: =SUM(B5:M5) -> 3714.98 | O5: 17921.8 | P5: =N5/O5 -> 0.20728833
A6: Sunday | B6: N/A | C6: N/A | D6: N/A | E6: N/A | F6: N/A | G6: 45.6 | H6: N/A | I6: N/A | J6: N/A | K6: N/A | L6: N/A | M6: N/A | N6: 0 | O6: 19133.9 | P6: =N6/O6 -> 0
A9: Budget | B9: 14000
A10: Total Weekly Spend | B10: =SUM(B2:M6) -> 24480.26
A11: Remaing Spend | B11: =SUM(B9-B10) -> -10480.26
A13: Weekly Food Revenue | B13: =SUM(O2:O6) -> 75397.3
A14: Weekly Cost % | B14: =B10/B13 -> 0.32468351
A17: End of week status
A18: list items over $100
A19: Items carrying over | B19: Amount | C19: Items discarded | D19: Amount
A20: Short Ribs | B20: 3662.58
A32: Total | B32: =sum(B20:B31) -> 3662.58 | D32: =sum(D20:D31) -> 0

Sheet Roister week of (615-619)
B1: CW | C1: Fortune | D1: Viola | E1: A1 Firewood | F1: Superior | G1: Regalis | H1: Aya | I1: Closed Loop | J1: Rocker Bros | K1: Cornille | L1: Rare Tea Cellar | M1: D'artagnan | N1: Steve's | O1: Turano | P1: Daily Spend | Q1: Food Revenue | R1: Daily Cost %
A2: Wednesday | B2: 4244.06 | C2: 1381.57 | E2: 390 | F2: 909.5 | G2: 293.95 | H2: 19.8 | N2: 100 | P2: =SUM(B2:O2) -> 7338.88 | Q2: 12424.7 | R2: =P2/Q2 -> 0.59066859
A3: Thursday | B3: 2959.02 | C3: 483.5 | F3: 290 | L3: 55 | P3: =SUM(B3:O3) -> 3787.52 | Q3: 13022.4 | R3: =P3/Q3 -> 0.29084654
A4: Friday | B4: 3798.23 | C4: 1120.17 | F4: 1346.43 | H4: 181.31 | J4: 1035.49 | L4: 55.95 | M4: 2742.04 | N4: 100 | O4: 277.41 | P4: =SUM(B4:O4) -> 10657.03 | Q4: 17201 | R4: =P4/Q4 -> 0.61955875
A5: Saturday | B5: 2588.44 | C5: 1948.4 | F5: 293 | P5: =SUM(B5:O5) -> 4829.84 | Q5: 23303.25 | R5: =P5/Q5 -> 0.20726036
A6: Sunday | B6: N/A | C6: N/A | D6: N/A | E6: N/A | F6: N/A | H6: 45.6 | I6: N/A | J6: N/A | K6: N/A | L6: N/A | N6: N/A | O6: N/A | P6: 0 | Q6: 18482.2 | R6: =P6/Q6 -> 0
A9: Budget | B9: 14000
A10: Total Weekly Spend | B10: =SUM(B2:O6) -> 26658.87
A11: Remaing Spend | B11: =SUM(B9-B10) -> -12658.87
A13: Weekly Food Revenue | B13: =SUM(Q2:Q6) -> 84433.55
A14: Weekly Cost % | B14: =B10/B13 -> 0.31573788
A17: End of week status
A18: list items over $100
A19: Items carrying over | B19: Amount | C19: Items discarded | D19: Amount
A32: Total | B32: =sum(B20:B31) -> 0 | D32: =sum(D20:D31) -> 0

Sheet Roister week of (621-26)
B1: CW | C1: Fortune | D1: Viola | E1: A1 Firewood | F1: Superior | G1: Aya | H1: Closed Loop | I1: Rocker Bros | J1: Testa | K1: Regalis | L1: Cornille | M1: Rare Tea Cellar | N1: Steve's | O1: Turano | P1: Daily Spend | Q1: Daily Revenue | R1: Daily Cost %
A2: Tuesday (buyout) | B2: 4468.31 | D2: 270.08 | E2: 390 | G2: 49.5 | H2: 242 | N2: 100 | P2: =SUM(B2:O2) -> 5519.89 | Q2: 15600 | R2: =P2/Q2 -> 0.3538391
A3: Thursday | B3: 2556.14 | C3: 801.43 | F3: 2128.55 | I3: 3046.55 | K3: 339.54 | M3: 188.85 | P3: =SUM(B3:O3) -> 9061.06 | Q3: 14013.6 | R3: =P3/Q3 -> 0.64659046
A4: Friday | B4: 2139.68 | C4: 1796.3 | F4: $966,80 | G4: 166.9 | M4: 60 | N4: 100 | O4: 277.41 | P4: =SUM(B4:O4) -> 4540.29 | Q4: 18065 | R4: =P4/Q4 -> 0.25133075
A5: Saturday | B5: 2173.74 | C5: 1169.94 | G5: 82.5 | P5: =SUM(B5:O5) -> 3426.18 | Q5: 19569.6 | R5: =P5/Q5 -> 0.17507665
A6: Sunday | B6: N/A | C6: N/A | D6: N/A | E6: N/A | F6: N/A | H6: N/A | J6: N/A | L6: N/A | M6: N/A | N6: N/A | O6: N/A | P6: 0 | Q6: =4337.15+10901 -> 15238.15 | R6: =P6/Q6 -> 0
A9: Budget | B9: 14000
A10: Total Weekly Spend | B10: =SUM(B2:O6) -> 22547.42
A11: Remaing Spend | B11: =SUM(B9-B10) -> -8547.42
A13: Weekly Food Revenue | B13: =SUM(Q2:Q6) -> 82486.35
A14: Weekly Cost % | B14: =B10/B13 -> 0.27334729
A17: End of week status
A18: list items over $100
A19: Items carrying over | B19: Amount | C19: Items discarded | D19: Amount
A32: Total | B32: =sum(B20:B31) -> 0 | D32: =sum(D20:D31) -> 0

Sheet Roister week of (629-73)
B1: CW | C1: Fortune | D1: Closed Loop | E1: A1 Firewood | F1: Superior | G1: Aya | H1: Rocker Bros | I1: Regalis | J1: Cornille | K1: Rare Tea Cellar | L1: Steve's | M1: Turano | N1: Daily Spend | O1: Daily Revenue | P1: Daily Cost %
A2: Tuesday/Wednesday | B2: 3650.7 | C2: 1373.24 | D2: 242 | E2: 390 | F2: 2982.6 | G2: 82.5 | H2: 1173.55 | K2: 162.65 | L2: 100 | N2: =SUM(B2:M2) -> 10157.24 | O2: 8453 | P2: =N2/O2 -> 1.2016136
A3: Thursday | B3: 2111.76 | N3: =SUM(B3:M3) -> 2111.76 | O3: 10247 | P3: =N3/O3 -> 0.20608568
A4: Friday | B4: 1538.23 | C4: 643.56 | F4: 1069.1 | G4: 227.5 | I4: 56.23 | L4: 100 | M4: 277.41 | N4: =SUM(B4:M4) -> 3912.03 | O4: 13983.8 | P4: =N4/O4 -> 0.27975443
A5: Saturday | B5: 2342.7 | C5: 1056.41 | G5: 82.5 | N5: =SUM(B5:M5) -> 3481.61 | O5: =3316+15249.5 -> 18565.5 | P5: =N5/O5 -> 0.18753117
A6: Sunday | B6: N/A | C6: N/A | D6: N/A | E6: N/A | F6: N/A | G6: N/A | H6: N/A | I6: N/A | J6: N/A | K6: N/A | L6: N/A | M6: N/A | N6: 0 | O6: 18508.8 | P6: =N6/O6 -> 0
A9: Budget | B9: 14000
A10: Total Weekly Spend | B10: =SUM(B2:M6) -> 19662.64
A11: Remaing Spend | B11: =SUM(B9-B10) -> -5662.64
A13: Weekly Food Revenue | B13: =SUM(O2:O6) -> 69758.1
A14: Weekly Cost % | B14: =B10/B13 -> 0.28186892
A17: End of week status
A18: list items over $100
A19: Items carrying over | B19: Amount | C19: Items discarded | D19: Amount
A32: Total | B32: =sum(B20:B31) -> 0 | D32: =sum(D20:D31) -> 0

Sheet Roister week of (75-710)
B1: CW | C1: Fortune | D1: Closed Loop | E1: A1 Firewood | F1: Superior | G1: Aya | H1: Rocker Bros | I1: D'artagnan | J1: Regalis | K1: Cornille | L1: Rare Tea Cellar | M1: Steve's | N1: Turano | O1: Daily Spend | P1: Daily Revenue | Q1: Daily Cost %
A2: Tuesday/Wednesday | B2: 3430.07 | C2: 604.75 | E2: 390 | G2: 82.5 | M2: 100 | O2: =SUM(B2:N2) -> 4607.32 | P2: 7888 | Q2: =O2/P2 -> 0.58409229
A3: Thursday | B3: 2342.8 | C3: 696.9 | F3: 870.05 | H3: 672.5 | J3: 260.72 | L3: 39 | O3: =SUM(B3:N3) -> 4881.97 | P3: 10906 | Q3: =O3/P3 -> 0.44764075
A4: Friday | B4: 2710.15 | C4: 201.78 | F4: 1754.05 | G4: 49.5 | I4: 1252.1 | M4: 100 | N4: 302.37 | O4: =SUM(B4:N4) -> 6369.95 | P4: 14630 | Q4: =O4/P4 -> 0.43540328
A5: Saturday | B5: 2621.28 | C5: 702.67 | J5: 136.58 | O5: =SUM(B5:N5) -> 3460.53 | P5: =4888+14419 -> 19307 | Q5: =O5/P5 -> 0.17923706
A6: Sunday | B6: N/A | C6: N/A | D6: N/A | E6: N/A | F6: N/A | G6: N/A | H6: N/A | J6: N/A | K6: N/A | L6: N/A | M6: N/A | N6: N/A | O6: 0 | P6: 17791.6 | Q6: =O6/P6 -> 0
A9: Budget | B9: 14000
A10: Total Weekly Spend | B10: =SUM(B2:N6) -> 19319.77
A11: Remaing Spend | B11: =SUM(B9-B10) -> -5319.77
A13: Weekly Food Revenue | B13: =SUM(P2:P6) -> 70522.6
A14: Weekly Cost % | B14: =B10/B13 -> 0.27395147
A17: End of week status
A18: list items over $100
A19: Items carrying over | B19: Amount | C19: Items discarded | D19: Amount
A32: Total | B32: =sum(B20:B31) -> 0 | D32: =sum(D20:D31) -> 0

Sheet Roister week of (712-717)
B1: CW | C1: Fortune | D1: Closed Loop | E1: A1 Firewood | F1: Superior | G1: Aya | H1: Rocker Bros | I1: D'artagnan | J1: Regalis | K1: Cornille | L1: Rare Tea Cellar | M1: Steve's | N1: Turano | O1: Daily Spend | P1: Daily Revenue | Q1: Daily Cost %
A2: Tuesday/Wednesday | B2: 4131.8 | C2: 618 | E2: 390 | F2: 1277.45 | G2: 49.5 | M2: 100 | O2: =SUM(B2:N2) -> 6566.75 | P2: 10545.84 | Q2: =O2/P2 -> 0.62268629
A3: Thursday | B3: 739.6 | C3: 709.33 | F3: 904.51 | G3: 194.5 | O3: =SUM(B3:N3) -> 2547.94 | P3: 14145.68 | Q3: =O3/P3 -> 0.18012142
A4: Friday | B4: 2899.89 | C4: 764.08 | G4: 49.5 | M4: 100 | N4: 302.37 | O4: =SUM(B4:N4) -> 4115.84 | P4: 12887.61 | Q4: =O4/P4 -> 0.3193641
A5: Saturday | B5: 2073.58 | C5: 542.98 | O5: =SUM(B5:N5) -> 2616.56 | P5: =4552.1+16729 -> 21281.1 | Q5: =O5/P5 -> 0.12295229
A6: Sunday | B6: N/A | C6: N/A | D6: N/A | E6: N/A | F6: N/A | G6: N/A | H6: N/A | J6: N/A | K6: N/A | L6: N/A | M6: N/A | N6: N/A | O6: 0 | P6: 14696.6 | Q6: =O6/P6 -> 0
A9: Budget | B9: 14000
A10: Total Weekly Spend | B10: =SUM(B2:N6) -> 15847.09 | C10: 21k
A11: Remaing Spend | B11: =SUM(B9-B10) -> -1847.09
A13: Weekly Food Revenue | B13: =SUM(P2:P6) -> 73556.83
A14: Weekly Cost % | B14: =B10/B13 -> 0.21544009
A17: End of week status
A18: list items over $100
A19: Items carrying over | B19: Amount | C19: Items discarded | D19: Amount
A32: Total | B32: =sum(B20:B31) -> 0 | D32: =sum(D20:D31) -> 0

Sheet Roister week of (719-724)
B1: CW | C1: Fortune | D1: Closed Loop | E1: A1 Firewood | F1: Superior | G1: Aya | H1: Rocker Bros | I1: D'artagnan | J1: Four Star | K1: Regalis | L1: Cornille | M1: Rare Tea Cellar | N1: Steve's | O1: Turano | P1: Daily Spend | Q1: Daily Revenue | R1: Daily Cost %
A2: Tuesday/Wednesday | B2: 4051.48 | C2: 1270.4 | E2: 260 | F2: 933.6 | G2: 49.5 | H2: 1793 | J2: 180 | M2: 33.9 | N2: 100 | P2: =SUM(B2:O2) -> 8671.88 | Q2: 15069.64 | R2: =P2/Q2 -> 0.57545369
A3: Thursday | B3: 2002.14 | C3: 205.09 | G3: 194.5 | P3: =SUM(B3:O3) -> 2401.73 | Q3: 13352.1 | R3: =P3/Q3 -> 0.17987657
A4: Friday | B4: 2457.27 | C4: 1386.56 | F4: 870.95 | G4: 49.5 | H4: 1099.31 | K4: 57.85 | L4: 3000 | M4: 25 | N4: 100 | O4: 302.37 | P4: =SUM(B4:O4) -> 9348.81 | Q4: 13200.2 | R4: =P4/Q4 -> 0.70823245
A5: Saturday | B5: 4291.02 | C5: 1098.12 | F5: 126 | P5: =SUM(B5:O5) -> 5515.14 | Q5: 19915.74 | R5: =P5/Q5 -> 0.27692368
A6: Sunday | B6: N/A | C6: N/A | D6: N/A | E6: N/A | F6: N/A | G6: N/A | H6: N/A | I6: N/A | J6: N/A | K6: N/A | L6: N/A | M6: N/A | N6: N/A | O6: N/A | P6: 0 | Q6: 15444 | R6: =P6/Q6 -> 0
B7: =sum(B2:B5) -> 12801.91
B8: 13211.75 | C8: =B8-B7 -> 409.84 | E8: CW
A9: Budget | B9: 14000 | E9: 44760 | F9: 0
A10: Total Weekly Spend | B10: =SUM(B2:O6) -> 25937.56 | E10: 44761 | F10: 2233.88
A11: Remaing Spend | B11: =SUM(B9-B10) -> -11937.56 | E11: 44762 | F11: 1925.2 | G11: 4159.08
E12: 44763 | F12: 2018.1
A13: Weekly Food Revenue | B13: =SUM(Q2:Q6) -> 76981.68 | E13: 44764 | F13: 2467.58
A14: Weekly Cost % | B14: =B10/B13 -> 0.33693159 | E14: 44765 | F14: 4291.02
E15: 44766 | F15: 0
F16: 12935.78 | G16: 13211.75 | H16: =G16-F16 -> 275.97
A17: End of week status
A18: list items over $100 | E18: Duplicate copy from 7/21 total:
A19: Items carrying over | B19: Amount | C19: Items discarded | D19: Amount
A20: Short Ribs | B20: 1138.79
A21: Jamon | B21: 390.66
A32: Total | B32: =sum(B20:B31) -> 1529.45 | D32: =sum(D20:D31) -> 0

Sheet Roister week of (726-731)
B1: CW | C1: Fortune | D1: Closed Loop | E1: A1 Firewood | F1: Superior | G1: Aya | H1: Rocker Bros | I1: D'artagnan | J1: Four Star | K1: Regalis | L1: Testa | M1: Cornille | N1: Rare Tea Cellar | O1: Steve's | P1: Turano | Q1: Daily Spend | R1: Daily Revenue | S1: Daily Cost %
A2: Tuesday/Wednesday | B2: 3937.84 | C2: 486.24 | E2: 260 | F2: 504 | G2: 49.5 | I2: 1138.79 | J2: 180 | K2: 147.19 | O2: 100 | Q2: =SUM(B2:P2) -> 6803.56 | R2: 9127.34 | S2: =Q2/R2 -> 0.74540447
A3: Thursday | B3: 1487.48 | C3: 819.54 | G3: 194.5 | Q3: =SUM(B3:P3) -> 2501.52 | R3: 9555 | S3: =Q3/R3 -> 0.2618022
A4: Friday | B4: 1804.99 | C4: 144.9 | F4: 272.98 | G4: 49.5 | H4: 1067.72 | L4: 136.35 | O4: 100 | P4: 302.37 | Q4: =SUM(B4:P4) -> 3878.81 | R4: 12853.4 | S4: =Q4/R4 -> 0.30177307
A5: Saturday | B5: 1153.48 | C5: 580.1 | M5: 1674.5 | Q5: =SUM(B5:P5) -> 3408.08 | R5: 16202 | S5: =Q5/R5 -> 0.21034934
A6: Sunday | B6: N/A | C6: N/A | D6: N/A | E6: N/A | F6: N/A | G6: N/A | H6: N/A | I6: N/A | J6: N/A | K6: N/A | L6: N/A | M6: N/A | N6: N/A | O6: N/A | P6: N/A | Q6: 0 | R6: 12304.46 | S6: =Q6/R6 -> 0
B7: =sum(B2:B5) -> 8383.79 | C7: =sum(C2:C5) -> 2030.78 | D7: =sum(D2:D5) -> 0 | E7: =sum(E2:E5) -> 260 | F7: =sum(F2:F5) -> 776.98 | G7: =sum(G2:G5) -> 293.5 | H7: =sum(H2:H5) -> 1067.72 | I7: =sum(I2:I5) -> 1138.79 | ... Q7: =sum(Q2:Q5) -> 16591.97
A9: Budget | B9: 14000
A10: Total Weekly Spend | B10: =SUM(B2:P6) -> 16591.97 | D10: Carryover Items from last week | F10: Jamon $390.66
A11: Remaing Spend | B11: =SUM(B9-B10) -> -2591.97 | F11: Crisp Film $212.62
F12: Short Ribs $1,138.79
A13: Weekly Food Revenue | B13: =SUM(R2:R6) -> 60042.2
A14: Weekly Cost % | B14: =B10/B13 -> 0.27633848
A17: End of week status
A18: list items over $100
A19: Items carrying over | B19: Amount | C19: Items discarded | D19: Amount
A20: Potato Pellets | B20: 136.35
A21: Olives | B21: 101.28
A32: Total | B32: =sum(B20:B31) -> 237.63 | D32: =sum(D20:D31) -> 0

Sheet Roister week of (82-87)
B1: CW | C1: Fortune | D1: Closed Loop | E1: A1 Firewood | F1: Superior | G1: Aya | H1: Rocker Bros | I1: D'artagnan | J1: Four Star | K1: Truffles | L1: Regalis | M1: Cornille | N1: Rare Tea Cellar | O1: Steve's | P1: Turano | Q1: Daily Spend | R1: Daily Revenue | S1: Daily Cost %
A2: Tuesday/Wednesday | B2: 4299.5 | C2: 960.39 | E2: 390 | F2: 504 | G2: 49.5 | H2: 1020.11 | J2: 180 | O2: 100 | Q2: =SUM(B2:P2) -> 7503.5 | R2: 8503 | S2: =Q2/R2 -> 0.88245325
A3: Thursday | B3: 881.83 | C3: 0 | I3: 492 | Q3: =SUM(B3:P3) -> 1373.83 | R3: 11756 | S3: =Q3/R3 -> 0.11686203
A4: Friday | B4: 1427.35 | C4: 324.9 | F4: 493.65 | G4: 161.5 | N4: 39 | O4: 100 | P4: 302.37 | Q4: =SUM(B4:P4) -> 2848.77 | R4: 13016 | S4: =Q4/R4 -> 0.21886678
A5: Saturday | B5: 999.72 | C5: 135.3 | D5: 600 | F5: 189.38 | G5: 33 | K5: 440 | M5: 1421.35 | Q5: =SUM(B5:P5) -> 3818.75 | R5: 15453.6 | S5: =Q5/R5 -> 0.24711071
A6: Sunday | B6: N/A | C6: N/A | D6: N/A | E6: N/A | F6: N/A | G6: N/A | H6: N/A | I6: N/A | J6: N/A | K6: N/A | L6: N/A | M6: N/A | N6: N/A | O6: N/A | P6: N/A | Q6: 0 | R6: 15326.6 | S6: =Q6/R6 -> 0
B7: =8135.61 -> 8135.61 | C7: 1425.59 | D7: 747 | E7: 340 | F7: 997.65 | G7: 244 | H7: 1269.47 | I7: 569.4 | J7: 180 | M7: 1421.35 | N7: 39
B8: =sum(B2:B5)-B7 -> -527.21 | C8: =sum(C2:C5)-C7 -> -5 | D8: =sum(D2:D5)-D7 -> -147 | E8: =sum(E2:E5)-E7 -> 50 | F8: =sum(F2:F5)-F7 -> 189.38 | G8: =sum(G2:G5)-G7 -> 0 | H8: =sum(H2:H5)-H7 -> -249.36 | I8: =sum(I2:I5)-I7 -> -77.4 | J8: =sum(J2:J5)-J7 -> 0 | M8: =sum(M2:M5)-M7 -> 0 | N8: =sum(N2:N5)-N7 -> 0
A9: Budget | B9: 12000 | E9: Truffle | F9: 440
A10: Total Weekly Spend | B10: =SUM(B2:P6) -> 15544.85
A11: Remaing Spend | B11: =SUM(B9-B10) -> -3544.85
A13: Weekly Food Revenue | B13: =SUM(R2:R6) -> 64055.2
A14: Weekly Cost % | B14: =B10/B13 -> 0.24267897
A17: End of week status
A18: list items over $100
A19: Items carrying over | B19: Amount | C19: Items discarded | D19: Amount
A20: Short Ribs | B20: 492.45
A32: Total | B32: =sum(B20:B31) -> 492.45 | D32: =sum(D20:D31) -> 0

Sheet Roister week of (89-814)
B1: CW | C1: Fortune | D1: Closed Loop | E1: A1 Firewood | F1: Superior | G1: Aya | H1: Rocker Bros | I1: D'artagnan | J1: Four Star | K1: Regalis | L1: Cornille | M1: Truffles | N1: Rare Tea Cellar | O1: Steve's | P1: Turano | Q1: Daily Spend | R1: Daily Revenue | S1: Daily Cost %
A2: Tuesday | B2: 3152.12 | C2: 625.65 | Q2: =SUM(B2:P2) -> 3777.77 | R2: 0 | S2: =Q2/R2 -> #DIV/0!
A3: Wednesday | B3: 740.16 | E3: 390 | F3: 685.63 | G3: 49.5 | I3: 492.45 | J3: 180 | N3: 44.5 | O3: 100 | Q3: =SUM(B3:P3) -> 2682.24 | R3: 8392.2 | S3: =Q3/R3 -> 0.31961107
A4: Thursday | B4: 1042.57 | C4: 189.45 | Q4: =SUM(B4:P4) -> 1232.02 | R4: 11455 | S4: =Q4/R4 -> 0.10755303
A5: Friday | B5: 2162.55 | C5: 491.16 | F5: 449.5 | G5: 161.5 | O5: 100 | P5: 306.93 | Q5: =SUM(B5:P5) -> 3671.64 | R5: 13821 | S5: =Q5/R5 -> 0.26565661
A6: Saturday | B6: 2486.32 | C6: 460.9 | G6: 33 | H6: 1122.96 | K6: 84.83 | L6: 1191.5 | M6: 440 | Q6: =SUM(B6:P6) -> 5819.51 | R6: 18719.4 | S6: =Q6/R6 -> 0.31088122
A7: Sunday | B7: N/A | C7: N/A | D7: N/A | E7: N/A | F7: N/A | G7: N/A | H7: N/A | I7: N/A | J7: N/A | K7: N/A | L7: N/A | M7: N/A | N7: N/A | O7: N/A | P7: N/A | Q7: 0 | R7: 12914.6 | S7: =Q7/R7 -> 0
B8: =sum(B2:B6) -> 9583.72 | C8: =sum(C2:C6) -> 1767.16 | D8: =sum(D2:D6) -> 0 | E8: =sum(E2:E6) -> 390 | F8: =sum(F2:F6) -> 1135.13 | G8: =sum(G2:G6) -> 244 | H8: =sum(H2:H6) -> 1122.96 | I8: =sum(I2:I6) -> 492.45 | ... P8: =sum(P2:P6) -> 306.93
B9: 10446.05 | C9: 1922 | D9: 477 | E9: 390 | F9: 1420.03 | G9: 244 | H9: 1122.96 | J9: 180 | K9: 84.83 | L9: 1191.5 | M9: 440 | N9: 44.5 | P9: 306.93
A10: Budget | B10: 14000 | C10: =B8-B9 -> -862.33 | F10: =F8-F9 -> -284.9
A11: Total Weekly Spend | B11: =SUM(B2:P7) -> 17183.18
A12: Remaing Spend | B12: =SUM(B10-B11) -> -3183.18
A14: Weekly Food Revenue | B14: =SUM(R3:R7) -> 65302.2
A15: Weekly Cost % | B15: =B11/B14 -> 0.26313325
A18: End of week status | G18: Scallops
A19: list items over $100 | G19: Date delivered | H19: Weight billed (lbs) | I19: Weight received (lbs)
A20: Items carrying over | B20: Amount | C20: Items discarded | D20: Amount | G20: 44783 | H20: 16# | I20: 16# | J20: 4# = 53pc
A21: Jamon | B21: 584.45 | G21: 44785 | H21: 12# | I21: 12#
A22: Short Ribs | B22: 1078.63
H28: Total left at EOW
I30: =16+12 -> 28
I31: =I30/90 -> 0.31111111
A33: Total | B33: =sum(B21:B32) -> 1663.08 | D33: =sum(D21:D32) -> 0

Sheet Roister week of (816-821)
B1: CW | C1: Fortune | D1: Closed Loop | E1: A1 Firewood | F1: Superior | G1: Aya | H1: Rocker Bros | I1: D'artagnan | J1: Four Star | K1: Regalis | L1: Cornille | M1: Truffles | N1: Rare Tea Cellar | O1: Steve's | P1: Turano | Q1: Daily Spend | R1: Daily Revenue | S1: Daily Cost %
A2: Tuesday | B2: 3999.84 | F2: 374.4 | I2: 1078.63 | Q2: =SUM(B2:P2) -> 5452.87 | R2: 0 | S2: =Q2/R2 -> #DIV/0!
A3: Wednesday | B3: 629.22 | C3: 433.37 | E3: 290 | F3: 298.51 | G3: 49.5 | H3: 1038.96 | J3: 180 | K3: 60.45 | M3: 440 | O3: 100 | Q3: =SUM(B3:P3) -> 3520.01 | R3: 10638.8 | S3: =Q3/R3 -> 0.33086532
A4: Thursday | B4: 1126.01 | C4: 161.66 | Q4: =SUM(B4:P4) -> 1287.67 | R4: 14444.95 | S4: =Q4/R4 -> 0.089143265
A5: Friday | B5: 934.83 | F5: 120 | G5: 161.5 | K5: 69.95 | O5: 100 | P5: 302.37 | Q5: =SUM(B5:P5) -> 1688.65 | R5: 14415.6 | S5: =Q5/R5 -> 0.11714046
A6: Saturday | B6: 2025.52 | C6: 762.15 | D6: 600 | G6: 33 | L6: 416.5 | Q6: =SUM(B6:P6) -> 3837.17 | R6: 18145.2 | S6: =Q6/R6 -> 0.21147025
A7: Sunday | B7: N/A | C7: N/A | D7: N/A | E7: N/A | F7: N/A | G7: N/A | H7: N/A | I7: N/A | J7: N/A | K7: N/A | L7: N/A | M7: N/A | N7: N/A | O7: N/A | P7: N/A | Q7: 0 | R7: 13500 | S7: =Q7/R7 -> 0
B8: 8363.82 | C8: 1591.91 | E8: 290 | F8: 898.51 | G8: 244 | H8: 1038.96 | I8: 1078.63 | J8: 180 | K8: 129.4 | L8: 416.5 | M8: 440
B9: =SUM(B2:B6)-B8 -> 351.6 | C9: =SUM(C2:C6)-C8 -> -234.73 | E9: =SUM(E2:E6)-E8 -> 0 | F9: =SUM(F2:F6)-F8 -> -105.6 | G9: =SUM(G2:G6)-G8 -> 0 | H9: =SUM(H2:H6)-H8 -> 0 | I9: =SUM(I2:I6)-I8 -> 0 | J9: =SUM(J2:J6)-J8 -> 0 | K9: =SUM(K2:K6)-K8 -> 1 | L9: =SUM(L2:L6)-L8 -> 0 | M9: =SUM(M2:M6)-M8 -> 0 | O9: =SUM(O2:O6)-O8 -> 200 | P9: =SUM(P2:P6)-P8 -> 302.37
A10: Budget | B10: 12000
A11: Total Weekly Spend | B11: =SUM(B2:P7) -> 15786.37
A12: Remaing Spend | B12: =SUM(B10-B11) -> -3786.37
A14: Weekly Food Revenue | B14: =SUM(R3:R7) -> 71144.55
A15: Weekly Cost % | B15: =B11/B14 -> 0.22189149
A18: End of week status | G18: Scallops
A19: list items over $100 | G19: Date delivered | H19: Weight billed (lbs) | I19: Weight received (lbs)
A20: Items carrying over | B20: Amount | C20: Items discarded | D20: Amount | G20: 44790 | H20: 16# | I20: 16#
A21: Trout | B21: 597.02 | G21: 44792 | H21: 4# | I21: 4#
A22: Short Ribs | B22: 1045.05
H28: Total left at EOW
A33: Total | B33: =sum(B21:B32) -> 1642.07 | D33: =sum(D21:D32) -> 0

Sheet Roister (913-918)
B1: CW | C1: Fortune | D1: Closed Loop | E1: A1 Firewood | F1: Superior | G1: Aya | H1: Rocker Bros | I1: D'artagnan | J1: Four Star | K1: Regalis | L1: Cornille | M1: Truffles | N1: Rare Tea Cellar | O1: Steve's | P1: Turano | Q1: Daily Spend | R1: Daily Revenue | S1: Daily Cost %
A2: Tuesday | B2: 3642.14 | Q2: =SUM(B2:P2) -> 3642.14 | S2: =Q2/R2 -> #DIV/0!
A3: Wednesday | B3: 839.16 | C3: 628.09 | E3: 390 | F3: 764.9 | G3: 49.5 | H3: 1087.23 | J3: 180 | O3: 100 | Q3: =SUM(B3:P3) -> 4038.88 | R3: 7126 | S3: =Q3/R3 -> 0.5667808
A4: Thursday | B4: 1663.26 | C4: 664.86 | K4: 82.6 | Q4: =SUM(B4:P4) -> 2410.72 | R4: 11095.83 | S4: =Q4/R4 -> 0.2172636
A5: Friday | B5: 2077.72 | C5: 196.19 | F5: 404.9 | G5: 142.5 | K5: 41.42 | O5: 100 | P5: 221.94 | Q5: =SUM(B5:P5) -> 3184.67 | R5: 13477 | S5: =Q5/R5 -> 0.23630407
A6: Saturday | B6: 1499.73 | C6: 350.89 | G6: 33 | L6: 924.7 | Q6: =SUM(B6:P6) -> 2808.32 | R6: 18696.8 | S6: =Q6/R6 -> 0.15020324
A7: Sunday | B7: N/A | C7: N/A | D7: N/A | E7: N/A | F7: N/A | G7: N/A | H7: N/A | I7: N/A | J7: N/A | K7: N/A | L7: N/A | M7: N/A | N7: N/A | O7: N/A | P7: N/A | Q7: 0 | R7: 8958 | S7: =Q7/R7 -> 0
A8: Reported on COGS | B8: 9795.36 | C8: 1948.6 | D8: 847 | E8: 390 | F8: 1628.93 | G8: 225 | H8: 1087.24 | J8: 180 | K8: 124.02 | L8: 924.7 | O8: 316.96 | P8: 221.94 | Q8: 325.55
B9: =sum(B2:B6)-B8 -> -73.35 | C9: =sum(C2:C6)-C8 -> -108.57 | D9: =sum(D2:D6)-D8 -> -847 | E9: =sum(E2:E6)-E8 -> 0 | F9: =sum(F2:F6)-F8 -> -459.13 | G9: =sum(G2:G6)-G8 -> 0 | H9: =sum(H2:H6)-H8 -> -0.01 | J9: =sum(J2:J6)-J8 -> 0 | K9: =sum(K2:K6)-K8 -> 0 | L9: =sum(L2:L6)-L8 -> 0 | O9: =sum(O2:O6)-O8 -> -116.96 | P9: =sum(P2:P6)-P8 -> 0 | Q9: =0-Q8 -> -325.55 | R9: Wabash Seafood
A10: Budget | B10: 12000 | F10: Trout carry over
A11: Total Weekly Spend | B11: =SUM(B2:P7) -> 16084.73
A12: Remaing Spend | B12: =SUM(B10-B11) -> -4084.73
A14: Weekly Food Revenue | B14: =SUM(R3:R7) -> 59353.63
A15: Weekly Cost % | B15: =B11/B14 -> 0.27099825
A18: End of week status | G18: Scallops
A19: list items over $100 | G19: Date delivered | H19: Weight billed (lbs) | I19: Weight received (lbs)
A20: Items carrying over | B20: Amount | C20: Items discarded | D20: Amount
A21: Jamon | B21: 511.12 | G21: 44818 | H21: 16# | I21: 16#
A22: Short Ribs | B22: 696.7 | G22: 44820 | H22: 4# | I22: 4#
H28: Total left at EOW
A33: Total | B33: =sum(B21:B32) -> 1207.82 | D33: =sum(D21:D32) -> 0

Sheet Roister week of (823-828)
B1: CW | C1: Fortune | D1: Closed Loop | E1: A1 Firewood | F1: Wabash | G1: Superior | H1: Aya | I1: Rocker Bros | J1: D'artagnan | K1: Four Star | L1: Regalis | M1: Cornille | N1: Truffles | O1: Rare Tea Cellar | P1: Steve's | Q1: Turano | R1: Daily Spend | S1: Daily Revenue | T1: Daily Cost %
A2: Tuesday | B2: 4162.17 | C2: 531.65 | G2: 298.51 | J2: 1045.05 | O2: 126.9 | R2: =SUM(B2:Q2) -> 6164.28 | S2: 0 | T2: =R2/S2 -> #DIV/0!
A3: Wednesday | B3: 355.18 | C3: 441.51 | F3: 289.58 | G3: 765.68 | H3: 49.5 | K3: 180 | P3: 100 | R3: =SUM(B3:Q3) -> 2181.45 | S3: 9165 | T3: =R3/S3 -> 0.23801964
A4: Thursday | B4: 1003.5 | R4: =SUM(B4:Q4) -> 1003.5 | S4: 11088 | T4: =R4/S4 -> 0.090503247
A5: Friday | B5: 1384.57 | C5: 238 | G5: 120 | H5: 142.5 | I5: 795.83 | N5: 440 | P5: 100 | Q5: 302.37 | R5: =SUM(B5:Q5) -> 3523.27 | S5: 13991.2 | T5: =R5/S5 -> 0.25182043
A6: Saturday | B6: 1493.52 | C6: 637.17 | D6: 600 | H6: 33 | M6: 1485.5 | R6: =SUM(B6:Q6) -> 4249.19 | S6: 18492.8 | T6: =R6/S6 -> 0.22977537
A7: Sunday | B7: N/A | C7: N/A | D7: N/A | E7: N/A | G7: N/A | H7: N/A | I7: N/A | J7: N/A | K7: N/A | L7: N/A | M7: N/A | N7: N/A | O7: N/A | P7: N/A | Q7: N/A | R7: 0 | S7: 14128 | T7: =R7/S7 -> 0
B8: 8650.91 | C8: 1995.44 | D8: 427 | E8: 280 | F8: 297.53 | G8: 885.68 | H8: 225 | I8: 795.83 | K8: 180 | M8: 1485.5 | N8: 440 | O8: 126.9
B9: =sum(B2:B6)-B8 -> -251.97 | C9: =sum(C2:C6)-C8 -> -147.11 | D9: =sum(D2:D6)-D8 -> 173 | E9: =sum(E2:E6)-E8 -> -280 | F9: =sum(F2:F6)-F8 -> -7.95 | G9: =sum(G2:G6)-G8 -> 298.51 | H9: =sum(H2:H6)-H8 -> 0 | I9: =sum(I2:I6)-I8 -> 0 | ... Q9: =sum(Q2:Q6)-Q8 -> 302.37
A10: Budget | B10: 14000
A11: Total Weekly Spend | B11: =SUM(B2:Q7) -> 17121.69
A12: Remaing Spend | B12: =SUM(B10-B11) -> -3121.69
A14: Weekly Food Revenue | B14: =SUM(S3:S7) -> 66865
A15: Weekly Cost % | B15: =B11/B14 -> 0.25606356
A18: End of week status | H18: Scallops
A19: list items over $100 | H19: Date delivered | I19: Weight billed (lbs) | J19: Weight received (lbs)
A20: Items carrying over | B20: Amount | C20: Items discarded | D20: Amount | H20: 44797 | I20: 16#
A21: Trout | B21: 298.51 | H21: 44799 | I21: 4#
A22: Potato Pellets | B22: 161.7
A23: Jamon | B23: 441.51
A24: Trout | B24: 895
I28: Total left at EOW
A33: Total | B33: =sum(B21:B32) -> 1796.72 | D33: =sum(D21:D32) -> 0

Sheet Roister (830-94)
B1: CW | C1: Fortune | D1: Closed Loop | E1: A1 Firewood | F1: Superior | G1: Aya | H1: Rocker Bros | I1: D'artagnan | J1: Four Star | K1: Regalis | L1: Cornille | M1: Truffles | N1: Rare Tea Cellar | O1: Steve's | P1: Turano | Q1: Daily Spend | R1: Daily Revenue | S1: Daily Cost %
A2: Tuesday | B2: 4048.52 | C2: 855.57 | F2: 298.51 | I2: 561 | Q2: =SUM(B2:P2) -> 5763.6 | S2: =Q2/R2 -> #DIV/0!
A3: Wednesday | B3: 1258.75 | C3: 82.05 | E3: 290 | F3: 1224.02 | G3: 49.5 | J3: 180 | O3: 100 | Q3: =SUM(B3:P3) -> 3184.32 | R3: 9178 | S3: =Q3/R3 -> 0.34695141
A4: Thursday | B4: 1054.62 | G4: 142.5 | I4: 507.84 | N4: 58.9 | Q4: =SUM(B4:P4) -> 1763.86 | R4: 7985 | S4: =Q4/R4 -> 0.22089668
A5: Friday | B5: 2230.81 | C5: 528.45 | F5: 120 | O5: 100 | P5: 306.93 | Q5: =SUM(B5:P5) -> 3286.19 | R5: 14292.8 | S5: =Q5/R5 -> 0.22991926
A6: Saturday | B6: 1367.3 | C6: 381.18 | D6: 600 | G6: 71 | H6: 1132.12 | L6: 972.5 | M6: 440 | Q6: =SUM(B6:P6) -> 4964.1 | R6: 18043.26 | S6: =Q6/R6 -> 0.27512212
A7: Sunday | B7: N/A | C7: N/A | D7: N/A | E7: N/A | F7: N/A | G7: N/A | H7: N/A | I7: N/A | J7: N/A | K7: N/A | L7: N/A | M7: N/A | N7: N/A | O7: N/A | P7: N/A | Q7: 0 | R7: 21919 | S7: =Q7/R7 -> 0
A10: Budget | B10: 14000
A11: Total Weekly Spend | B11: =SUM(B2:P7)+sum(B21:B24) -> 21662.43
A12: Remaing Spend | B12: =SUM(B10-B11) -> -7662.43
A14: Weekly Food Revenue | B14: =SUM(R3:R7) -> 71418.06
A15: Weekly Cost % | B15: =B11/B14 -> 0.30331866
A18: End of week status | G18: Scallops
A19: list items over $100 | G19: Date delivered | H19: Weight billed (lbs) | I19: Weight received (lbs)
A20: Items carrying over | B20: Amount | C20: Items discarded | D20: Amount | G20: 44804 | H20: 16# | I20: 16#
A21: Trout | B21: 298.51 | G21: 44806 | H21: 4# | I21: 4#
A22: Jamon | B22: 441.51
A23: Trout | B23: 895
A24: Short Ribs | B24: 1065.34
H28: Total left at EOW
A33: Total | B33: =sum(B21:B32) -> 2700.36 | D33: =sum(D21:D32) -> 0

Sheet Roister (96-911)
B1: CW | C1: Fortune | D1: Closed Loop | E1: A1 Firewood | F1: Superior | G1: Aya | H1: Rocker Bros | I1: D'artagnan | J1: Four Star | K1: Regalis | L1: Cornille | M1: Truffles | N1: Rare Tea Cellar | O1: Steve's | P1: Turano | Q1: Daily Spend | R1: Daily Revenue | S1: Daily Cost %
A2: Tuesday | B2: 3362.87 | F2: 459.15 | I2: 1065.34 | Q2: =SUM(B2:P2) -> 4887.36 | S2: =Q2/R2 -> #DIV/0!
A3: Wednesday | B3: 1263.4 | C3: 767.89 | E3: 390 | F3: 884.9 | G3: 49.5 | J3: 180 | K3: 326.99 | O3: 100 | Q3: =SUM(B3:P3) -> 3962.68 | R3: 11182.98 | S3: =Q3/R3 -> 0.3543492
A4: Thursday | B4: 1331.79 | N4: 64 | Q4: =SUM(B4:P4) -> 1395.79 | R4: 7765.5 | S4: =Q4/R4 -> 0.17974245
A5: Friday | B5: 1928.48 | C5: 673.95 | F5: 284.9 | G5: 142.5 | K5: 100.66 | M5: 440 | O5: 100 | P5: 306.93 | Q5: =SUM(B5:P5) -> 3977.42 | R5: 13255 | S5: =Q5/R5 -> 0.30006941
A6: Saturday | B6: 2049.67 | C6: 197.24 | D6: 600 | G6: 33 | H6: 716.37 | L6: 1482.2 | Q6: =SUM(B6:P6) -> 5078.48 | R6: 17911.9 | S6: =Q6/R6 -> 0.28352548
A7: Sunday | B7: N/A | C7: N/A | D7: N/A | E7: N/A | F7: N/A | G7: N/A | H7: N/A | I7: N/A | J7: N/A | K7: N/A | L7: N/A | M7: N/A | N7: N/A | O7: N/A | P7: N/A | Q7: 0 | R7: 11186.2 | S7: =Q7/R7 -> 0
A10: Budget | B10: 14000
A11: Total Weekly Spend | B11: =SUM(B2:P7) -> 19301.73
A12: Remaing Spend | B12: =SUM(B10-B11) -> -5301.73
A14: Weekly Food Revenue | B14: =SUM(R3:R7) -> 61301.58
A15: Weekly Cost % | B15: =B11/B14 -> 0.31486513
A18: End of week status | G18: Scallops
A19: list items over $100 | G19: Date delivered | H19: Weight billed (lbs) | I19: Weight received (lbs)
A20: Items carrying over | B20: Amount | C20: Items discarded | D20: Amount | G20: 44811 | H20: 20# | I20: 20#
A21: Trout | B21: 459.13
A22: Short Ribs | B22: 1065.35
H28: Total left at EOW
A33: Total | B33: =sum(B21:B32) -> 1524.48 | D33: =sum(D21:D32) -> 0

Sheet Roister (920 - 925)
B1: CW | C1: Fortune | D1: Closed Loop | E1: A1 Firewood | F1: Superior | G1: Aya | H1: Rocker Bros | I1: D'artagnan | J1: Four Star | K1: Regalis | L1: Cornille | M1: Truffles | N1: Rare Tea Cellar | O1: Steve's | P1: Turano | Q1: Daily Spend | R1: Daily Revenue | S1: Daily Cost %
A2: Tuesday | B2: 3745.04 | C2: 511.22 | I2: 696.7 | Q2: =SUM(B2:P2) -> 4952.96 | R2: 13096.56 | S2: =Q2/R2 -> 0.37818786
A3: Wednesday | B3: 1080.82 | C3: 432.52 | E3: 390 | G3: 49.5 | J3: 180 | O3: 100 | Q3: =SUM(B3:P3) -> 2232.84 | R3: 23246 | S3: =Q3/R3 -> 0.096052654
A4: Thursday | Q4: =SUM(B4:P4) -> 0 | S4: =Q4/R4 -> #DIV/0!
A5: Friday | B5: 2387.65 | F5: 764.9 | G5: 142.5 | M5: 440 | N5: 72.9 | O5: 100 | P5: 302.37 | Q5: =SUM(B5:P5) -> 4210.32 | R5: 13789.26 | S5: =Q5/R5 -> 0.30533328
A6: Saturday | B6: 1348.79 | C6: 610.44 | D6: 473 | H6: 943.7 | L6: 577 | Q6: =SUM(B6:P6) -> 3952.93 | R6: 17199.04 | S6: =Q6/R6 -> 0.22983434
A7: Sunday | B7: N/A | C7: N/A | D7: N/A | E7: N/A | F7: N/A | G7: N/A | H7: N/A | I7: N/A | J7: N/A | K7: N/A | L7: N/A | M7: N/A | N7: N/A | O7: N/A | P7: N/A | Q7: 0 | R7: 16078 | S7: =Q7/R7 -> 0
A8: Reported on COGS | B8: 8338.39 | C8: 1188.51 | D8: 473 | E8: 390 | F8: 764.9 | G8: 225 | H8: 1518.7 | I8: 2147.46 | J8: 180 | L8: 577 | M8: 440 | P8: 221.94
B9: =sum(B2:B6)-B8 -> 223.91 | C9: =sum(C2:C6)-C8 -> 365.67 | D9: =sum(D2:D6)-D8 -> 0 | E9: =sum(E2:E6)-E8 -> 0 | F9: =sum(F2:F6)-F8 -> 0 | G9: =sum(G2:G6)-G8 -> -33 | H9: =sum(H2:H6)-H8 -> -575 | I9: =sum(I2:I6)-I8 -> -1450.76 | ... M9: =sum(M2:M6)-M8 -> 0 | O9: =sum(O2:O6)-O8 -> 200 | P9: =sum(P2:P6)-P8 -> 80.43 | Q9: =0-Q8 -> 0
A10: Budget | B10: 12000
A11: Total Weekly Spend | B11: =SUM(B2:P7) -> 15349.05
A12: Remaing Spend | B12: =SUM(B10-B11) -> -3349.05
A14: Weekly Food Revenue | B14: =SUM(R3:R7) -> 70312.3
A15: Weekly Cost % | B15: =B11/B14 -> 0.21829822
A18: End of week status | G18: Scallops
A19: list items over $100 | G19: Date delivered | H19: Weight billed (lbs) | I19: Weight received (lbs)
A20: Items carrying over | B20: Amount | C20: Items discarded | D20: Amount | G20: 44827 | H20: 16# | I20: 16#
A21: Jamon | B21: 511.12
A22: Short Ribs | B22: 1061.84
H28: Total left at EOW
A33: Total | B33: =sum(B21:B32) -> 1572.96 | D33: =sum(D21:D32) -> 0

Sheet Roister (926 - 102)
B1: CW | C1: Fortune | D1: Closed Loop | E1: A1 Firewood | F1: Superior | G1: Aya | H1: Rocker Bros | I1: D'artagnan | J1: Four Star | K1: Regalis | L1: Cornille | M1: Truffles | N1: Rare Tea Cellar | O1: Steve's | P1: Turano | Q1: Daily Spend | R1: Daily Revenue | S1: Daily Cost %
A2: Monday | B2: 2822.86 | C2: 444.21 | Q2: =SUM(B2:P2) -> 3267.07 | R2: 5074.85 | S2: =Q2/R2 -> 0.64377666
A3: Tuesday | B3: 1615.02 | F3: 566.65 | I3: 1061.84 | Q3: =SUM(B3:P3) -> 3243.51 | R3: 4921 | S3: =Q3/R3 -> 0.65911603
A4: Wednesday | B4: 1946.22 | C4: 344.86 | E4: 390 | F4: 240 | G4: 49.5 | J4: 180 | N4: 85 | O4: 100 | Q4: =SUM(B4:P4) -> 3335.58 | R4: 7563.4 | S4: =Q4/R4 -> 0.44101595
A5: Thursday | B5: 1896.93 | C5: 318.91 | Q5: =SUM(B5:P5) -> 2215.84 | R5: 9782.85 | S5: =Q5/R5 -> 0.2265025
A6: Friday | B6: 1692.84 | C6: 65.79 | F6: 284.9 | G6: 142.5 | M6: 440 | O6: 100 | P6: 302.37 | Q6: =SUM(B6:P6) -> 3028.4 | R6: 27222.3 | S6: =Q6/R6 -> 0.11124703
A7: Saturday | B7: 1743.99 | C7: 323.7 | D7: 438 | G7: 33 | H7: 1038.22 | L7: 453 | Q7: =SUM(B7:P7) -> 4029.91 | R7: 20347.16 | S7: =Q7/R7 -> 0.19805762
A8: Sunday | B8: N/A | C8: N/A | D8: N/A | E8: N/A | F8: N/A | G8: N/A | H8: N/A | I8: N/A | J8: N/A | K8: N/A | L8: N/A | M8: N/A | N8: N/A | O8: N/A | P8: N/A | Q8: 0 | S8: =Q8/R8 -> #DIV/0!
B9: 11558.76 | C9: 1873.21 | D9: 906 | E9: 390 | F9: 1091.55 | G9: 225 | H9: 1049.76 | J9: 180 | L9: 595 | M9: 440 | N9: 85 | P9: 221.94
B10: =sum(B2:B7)-B9 -> 159.1 | C10: =sum(C2:C7)-C9 -> -375.74 | D10: =sum(D2:D7)-D9 -> -468 | E10: =sum(E2:E7)-E9 -> 0 | F10: =sum(F2:F7)-F9 -> 0 | G10: =sum(G2:G7)-G9 -> 0 | H10: =sum(H2:H7)-H9 -> -11.54 | I10: =sum(I2:I7)-I9 -> 1061.84 | ... P10: =sum(P2:P7)-P9 -> 80.43
A11: Budget | B11: 12000
A12: Total Weekly Spend | B12: =SUM(B2:P8) -> 19120.31
A13: Remaing Spend | B13: =SUM(B11-B12) -> -7120.31
A15: Weekly Food Revenue | B15: =SUM(R2:R8) -> 74911.56
A16: Weekly Cost % | B16: =B12/B15 -> 0.25523844
A19: End of week status | G19: Scallops
A20: list items over $100 | G20: Date delivered | H20: Weight billed (lbs) | I20: Weight received (lbs)
A21: Items carrying over | B21: Amount | C21: Items discarded | D21: Amount | G21: 44831 | H21: 8.75# | I21: 8.75#
A22: Short Ribs | B22: 1453.28 | G22: 44832 | H22: 8# | I22: 8#
H29: Total left at EOW
A34: Total | B34: =sum(B22:B33) -> 1453.28 | D34: =sum(D22:D33) -> 0

Sheet Roister (103 - 109)
B1: CW | C1: Fortune | D1: Closed Loop | E1: A1 Firewood | F1: Superior | G1: Aya | H1: Rocker Bros | I1: D'artagnan | J1: Four Star | K1: Regalis | L1: Cornille | M1: Truffles | N1: Rare Tea Cellar | O1: Steve's | P1: Turano | Q1: Daily Spend | R1: Daily Revenue | S1: Daily Cost %
A2: 44837 | B2: 2583.21 | C2: 1070.23 | I2: 1453.28 | Q2: =SUM(B2:P2) -> 5106.72 | R2: 6942.4 | S2: =Q2/R2 -> 0.73558424 | T2: =A2 -> 44837
A3: 44838 | B3: 2262.57 | C3: 133.15 | Q3: =SUM(B3:P3) -> 2395.72 | R3: 6371.65 | S3: =Q3/R3 -> 0.3759968 | T3: =A3 -> 44838
A4: 44839 | B4: 1448.37 | E4: 390 | F4: 748.9 | G4: 49.5 | J4: 300 | M4: 440 | O4: 100 | Q4: =SUM(B4:P4) -> 3476.77 | R4: 7168 | S4: =Q4/R4 -> 0.48504046 | T4: =A4 -> 44839
A5: 44840 | B5: 1487.24 | C5: 50 | N5: 50.85 | Q5: =SUM(B5:P5) -> 1588.09 | R5: 8632 | S5: =Q5/R5 -> 0.18397706 | T5: =A5 -> 44840
A6: 44841 | B6: 2456.99 | F6: 516.9 | G6: 142.5 | O6: 100 | P6: 221.94 | Q6: =SUM(B6:P6) -> 3438.33 | R6: 11710 | S6: =Q6/R6 -> 0.2936234 | T6: =A6 -> 44841
A7: 44842 | B7: 1573.9 | C7: 449.52 | D7: 882 | G7: 33 | H7: 495.48 | L7: 1000 | Q7: =SUM(B7:P7) -> 4433.9 | R7: 17551 | S7: =Q7/R7 -> 0.25262948 | T7: =A7 -> 44842
A8: 44843 | B8: N/A | C8: N/A | D8: N/A | E8: N/A | F8: N/A | G8: N/A | H8: N/A | I8: N/A | J8: N/A | K8: N/A | L8: N/A | M8: N/A | N8: N/A | O8: N/A | P8: N/A | Q8: 0 | R8: 13629.15 | S8: =Q8/R8 -> 0 | T8: =A8 -> 44843
Q9: Wabash seafood
A10: Actuals | B10: 11334.13 | C10: 1702.9 | D10: 882 | E10: 390 | F10: 1265.8 | G10: 258 | H10: 495.48 | I10: 1453.28 | L10: 969 | M10: 513.98 | N10: 50.85 | O10: 466.62 | P10: 221.94 | Q10: 488.35
A11: Difference | B11: =sum(B2:B8)-B10 -> 478.15 | C11: =sum(C2:C8)-C10 -> 0 | D11: =sum(D2:D8)-D10 -> 0 | E11: =sum(E2:E8)-E10 -> 0 | F11: =sum(F2:F8)-F10 -> 0 | G11: =sum(G2:G8)-G10 -> -33 | H11: =sum(H2:H8)-H10 -> 0 | I11: =sum(I2:I8)-I10 -> 0 | ... P11: =sum(P2:P8)-P10 -> 0 | Q11: =Q10-0 -> 488.35
A13: Budget | B13: 12000
A14: Total Weekly Spend | B14: =SUM(B2:P8) -> 20439.53
A15: Remaing Spend | B15: =SUM(B13-B14) -> -8439.53
A17: Weekly Food Revenue | B17: =SUM(R2:R8) -> 72004.2
A18: Weekly Cost % | B18: =B14/B17 -> 0.2838658
A21: End of week status | G21: Scallops
A22: list items over $100 | G22: Date delivered | H22: Weight billed (lbs) | I22: Weight received (lbs)
A23: Items carrying over | B23: Amount | C23: Items discarded | D23: Amount
A24: Jamon | B24: 431.37
H31: Total left at EOW
A36: Total | B36: =sum(B24:B35) -> 431.37 | D36: =sum(D24:D35) -> 0

Sheet Roister (1010 - 1016)
B1: CW | C1: Fortune | D1: Closed Loop | E1: A1 Firewood | F1: Superior | G1: Aya | H1: Rocker Bros | I1: D'artagnan | J1: Four Star | K1: Regalis | L1: Cornille | M1: Truffles | N1: Rare Tea Cellar | O1: Steve's | P1: Turano | Q1: Daily Spend | R1: Daily Revenue | S1: Daily Cost %
A2: 44844 | B2: 3070.18 | C2: 50 | J2: 180 | Q2: =SUM(B2:P2) -> 3300.18 | R2: 8964 | S2: =Q2/R2 -> 0.3681593 | T2: ='Roister (1010 - 1016)'!A2 -> 44844
A3: 44845 | B3: 2364.25 | C3: 604.66 | Q3: =SUM(B3:P3) -> 2968.91 | R3: 6832 | S3: =Q3/R3 -> 0.43455943 | T3: ='Roister (1010 - 1016)'!A3 -> 44845
A4: 44846 | B4: 1820.05 | C4: 204.17 | E4: 390 | F4: 922.9 | G4: 49.5 | O4: 100 | Q4: =SUM(B4:P4) -> 3486.62 | R4: 7365.6 | S4: =Q4/R4 -> 0.47336537 | T4: ='Roister (1010 - 1016)'!A4 -> 44846
A5: 44847 | B5: 1934.91 | C5: 209.2 | K5: 129.19 | Q5: =SUM(B5:P5) -> 2273.3 | R5: 7981.4 | S5: =Q5/R5 -> 0.28482472 | T5: ='Roister (1010 - 1016)'!A5 -> 44847
A6: 44848 | B6: 1401.16 | C6: 537.49 | F6: 632.9 | G6: 142.5 | O6: 100 | P6: 302.37 | Q6: =SUM(B6:P6) -> 3116.42 | R6: 12383.2 | S6: =Q6/R6 -> 0.25166516 | T6: ='Roister (1010 - 1016)'!A6 -> 44848
A7: 44849 | B7: 1905.34 | C7: 290.91 | D7: 228.5 | G7: 33 | H7: 885.7 | L7: 1727.5 | Q7: =SUM(B7:P7) -> 5070.95 | R7: 17276 | S7: =Q7/R7 -> 0.2935257 | T7: ='Roister (1010 - 1016)'!A7 -> 44849
A8: 44850 | B8: N/A | C8: N/A | D8: N/A | E8: N/A | F8: N/A | G8: N/A | H8: N/A | I8: N/A | J8: N/A | K8: N/A | L8: N/A | M8: N/A | N8: N/A | O8: N/A | P8: N/A | Q8: 0 | R8: 11233 | S8: =Q8/R8 -> 0 | T8: ='Roister (1010 - 1016)'!A8 -> 44850
A11: Budget | B11: 14000
A12: Total Weekly Spend | B12: =SUM(B2:P8) -> 20216.38
A13: Remaing Spend | B13: =SUM(B11-B12) -> -6216.38
A15: Weekly Food Revenue | B15: =SUM(R2:R8) -> 72035.2
A16: Weekly Cost % | B16: =B12/B15 -> 0.28064585
A19: End of week status | G19: Scallops
A20: list items over $100 | G20: Date delivered | H20: Weight billed (lbs) | I20: Weight received (lbs)
A21: Items carrying over | B21: Amount | C21: Items discarded | D21: Amount
A22: Short Rib | B22: 1338.36
A23: Trout | B23: 686.64
A24: Cheddar | B24: 129.19
H29: Total left at EOW
A34: Total | B34: =sum(B22:B33) -> 2154.19 | D34: =sum(D22:D33) -> 0

Sheet Roister (1017-1023)
B1: CW | C1: Fortune | D1: Closed Loop | E1: A1 Firewood | F1: Superior | G1: Aya | H1: Rocker Bros | I1: D'artagnan | J1: Four Star | K1: Regalis | L1: Cornille | M1: Truffles | N1: Rare Tea Cellar | O1: Steve's | P1: Turano | Q1: Daily Spend | R1: Daily Revenue | S1: Daily Cost %
A2: 44851 | B2: 3671.82 | C2: 594.91 | F2: 343.32 | I2: 1338.36 | J2: 441.97 | K2: 129.19 | O2: 100 | Q2: =SUM(B2:P2) -> 6619.57 | R2: 7080.5 | S2: =Q2/R2 -> 0.93490149 | T2: =A2 -> 44851
A3: 44852 | B3: 1298.79 | C3: 63.45 | Q3: =SUM(B3:P3) -> 1362.24 | R3: 6313.1 | S3: =Q3/R3 -> 0.21577989 | T3: =A3 -> 44852
A4: 44853 | B4: 855.25 | C4: 574.78 | E4: 390 | F4: 748.9 | G4: 49.5 | O4: 100 | Q4: =SUM(B4:P4) -> 2718.43 | R4: 6976 | S4: =Q4/R4 -> 0.3896832 | T4: =A4 -> 44853
A5: 44854 | B5: 2150.1 | C5: 315.71 | N5: 61.9 | Q5: =SUM(B5:P5) -> 2527.71 | R5: 7550.4 | S5: =Q5/R5 -> 0.33477829 | T5: =A5 -> 44854
A6: 44855 | B6: 2000.37 | C6: 247.26 | F6: 748.9 | G6: 142.5 | K6: 116.45 | O6: 100 | P6: 221.94 | Q6: =SUM(B6:P6) -> 3577.42 | R6: 11938.6 | S6: =Q6/R6 -> 0.29965155 | T6: =A6 -> 44855
A7: 44856 | B7: 2206.37 | C7: 332.41 | D7: 876 | G7: 33 | H7: 379.35 | L7: 912 | Q7: =SUM(B7:P7) -> 4739.13 | R7: 13995.4 | S7: =Q7/R7 -> 0.33862055 | T7: =A7 -> 44856
A8: 44857 | B8: N/A | C8: N/A | D8: N/A | E8: N/A | F8: N/A | G8: N/A | H8: N/A | I8: N/A | J8: N/A | K8: N/A | L8: N/A | M8: N/A | N8: N/A | O8: N/A | P8: N/A | Q8: 0 | R8: 10065.2 | S8: =Q8/R8 -> 0 | T8: =A8 -> 44857
Q9: Spirit Tea | R9: Wabash
A10: Actuals | B10: 13968.7 | C10: 2850.99 | D10: 876 | E10: 390 | F10: 1841.12 | G10: 225 | H10: 663.53 | I10: 1898.41 | J10: 441.97 | K10: 245.64 | L10: 912 | M10: 424 | N10: 61.9 | O10: 316.96 | P10: 221.94 | Q10: 242.77 | R10: 415.43
A11: Difference | B11: =sum(B2:B8)-B10 -> -1786 | C11: =sum(C2:C8)-C10 -> -722.47 | D11: =sum(D2:D8)-D10 -> 0 | E11: =sum(E2:E8)-E10 -> 0 | F11: =sum(F2:F8)-F10 -> 0 | G11: =sum(G2:G8)-G10 -> 0 | H11: =sum(H2:H8)-H10 -> -284.18 | I11: =sum(I2:I8)-I10 -> -560.05 | ... P11: =sum(P2:P8)-P10 -> 0 | Q11: =Q10-0 -> 242.77 | R11: =R10-0 -> 415.43
E12: CW
A13: Budget | B13: 12000 | E13: 44851 | F13: 3671.74
A14: Total Weekly Spend | B14: =SUM(B2:P8) -> 21544.5 | E14: 44852 | F14: 1298.79
A15: Remaing Spend | B15: =SUM(B13-B14) -> -9544.5 | E15: 44853 | F15: 825.31
E16: 44854 | F16: 2016.69
A17: Weekly Food Revenue | B17: =SUM(R2:R8) -> 63919.2 | E17: 44855 | F17: 1994.43
A18: Weekly Cost % | B18: =B14/B17 -> 0.33705835 | E18: 44856 | F18: 1961.87
E19: Total | F19: 11768.83
A21: End of week status | G21: Scallops
A22: list items over $100 | G22: Date delivered | H22: Weight billed (lbs) | I22: Weight received (lbs)
A23: Items carrying over | B23: Amount | C23: Items discarded | D23: Amount | G23: 44853
A24: Trout | B24: 343.32
A25: Duck | B25: 381.3
A26: Jamon | B26: 465.59
A27: Short Rib | B27: 560.05
A28: Short Rib | B28: 312.78
H31: Total left at EOW
A36: Total | B36: =sum(B24:B35) -> 2063.04 | D36: =sum(D24:D35) -> 0

Sheet Roister (1024-1030)
B1: CW | C1: Fortune | D1: Closed Loop | E1: A1 Firewood | F1: Superior | G1: Aya | H1: Rocker Bros | I1: D'artagnan | J1: Four Star | K1: Regalis | L1: Cornille | M1: Truffles | N1: Rare Tea Cellar | O1: Steve's | P1: Turano | Q1: Daily Spend | R1: Daily Revenue | S1: Daily Cost %
A2: 44858 | B2: 1880.22 | C2: 778.37 | F2: 343.32 | H2: 381.3 | I2: 560.05 | J2: 180 | M2: 424 | O2: 100 | Q2: =SUM(B2:P2) -> 4647.26 | R2: 5113.6 | S2: =Q2/R2 -> 0.90880397 | T2: =A2 -> 44858
A3: 44859 | B3: 1957.31 | C3: 242.4 | K3: 97.75 | N3: 16.95 | Q3: =SUM(B3:P3) -> 2314.41 | R3: 7416.4 | S3: =Q3/R3 -> 0.3120665 | T3: =A3 -> 44859
A4: 44860 | B4: 1227.57 | C4: 718.67 | E4: 390 | F4: 649.95 | G4: 49.5 | O4: 100 | Q4: =SUM(B4:P4) -> 3135.69 | R4: 7212.26 | S4: =Q4/R4 -> 0.43477218 | T4: =A4 -> 44860
A5: 44861 | B5: 1133.02 | C5: 93.28 | Q5: =SUM(B5:P5) -> 1226.3 | R5: 6019 | S5: =Q5/R5 -> 0.20373816 | T5: =A5 -> 44861
A6: 44862 | B6: 1687.16 | C6: 238.59 | G6: 142.5 | O6: 100 | P6: 221.94 | Q6: =SUM(B6:P6) -> 2390.19 | R6: 10827 | S6: =Q6/R6 -> 0.22076198 | T6: =A6 -> 44862
A7: 44863 | B7: 1034.79 | C7: 192.23 | D7: 362 | G7: 33 | H7: 625.07 | L7: 766.5 | Q7: =SUM(B7:P7) -> 3013.59 | R7: 13140.5 | S7: =Q7/R7 -> 0.22933602 | T7: =A7 -> 44863
A8: 44864 | B8: N/A | C8: N/A | D8: N/A | E8: N/A | F8: N/A | G8: N/A | H8: N/A | I8: N/A | J8: N/A | K8: N/A | L8: N/A | M8: N/A | N8: N/A | O8: N/A | P8: N/A | Q8: 0 | R8: 8890.5 | S8: =Q8/R8 -> 0 | T8: =A8 -> 44864
Q9: Wabash | R9: Wine dinner
A10: Actuals | B10: 8904.62 | C10: 2463.54 | D10: 418 | E10: 390 | F10: 1526.85 | G10: 225 | H10: 625.07 | I10: 2046.35 | J10: 180 | K10: 97.75 | L10: 810.75 | M10: 424 | N10: 16.95 | O10: 466.62 | Q10: 257.99 | R10: 413.23
A11: Difference | B11: =sum(B2:B8)-B10 -> 15.45 | C11: =sum(C2:C8)-C10 -> -200 | D11: =sum(D2:D8)-D10 -> -56 | E11: =sum(E2:E8)-E10 -> 0 | F11: =sum(F2:F8)-F10 -> -533.58 | G11: =sum(G2:G8)-G10 -> 0 | H11: =sum(H2:H8)-H10 -> 381.3 | I11: =sum(I2:I8)-I10 -> -1486.3 | ... P11: =sum(P2:P8)-P10 -> 221.94 | Q11: =Q10-0 -> 257.99 | R11: =R10-0 -> 413.23
L12: Currently using an estimate
A13: Budget | B13: 12000 | F13: Superior - in COGS | O13: Steve's - COGS
A14: Total Weekly Spend | B14: =SUM(B2:P8) -> 16727.44 | C14: 18414 | D14: =C14-B14 -> 1686.56 | F14: 10/26 - 1009.95 | O14: Includes sunflowers, tax, and delivery fee
A15: Remaing Spend | B15: =SUM(B13-B14) -> -4727.44 | F15: 10/28 - 516.9
A17: Weekly Food Revenue | B17: =SUM(R2:R8) -> 58619.26
A18: Weekly Cost % | B18: =B14/B17 -> 0.28535741
A21: End of week status | G21: Scallops
A22: list items over $100 | G22: Date delivered | H22: Weight billed (lbs) | I22: Weight received (lbs)
A23: Items carrying over | B23: Amount | C23: Items discarded | D23: Amount | G23: 44858 | H23: 16# | I23: 16#
A24: Scallops | B24: 380 | G24: 44862 | H24: 8#
A25: Oysters | B25: 200
H31: Total left at EOW
A36: Total | B36: =sum(B24:B35) -> 580 | D36: =sum(D24:D35) -> 0

Sheet Roister (1031-116)
B1: CW | C1: Fortune | D1: Closed Loop | E1: A1 Firewood | F1: Wabash | G1: Superior | H1: Aya | I1: Rocker Bros | J1: D'artagnan | K1: Four Star | L1: Regalis | M1: Cornille | N1: Truffles | O1: Rare Tea Cellar | P1: Steve's | Q1: Turano | R1: Daily Spend | S1: Daily Revenue | T1: Daily Cost %
A2: 44865 | B2: 1230.47 | C2: 315.71 | G2: 380 | J2: 1335.17 | K2: 180 | N2: 424 | P2: 100 | R2: =SUM(B2:Q2) -> 3965.35 | S2: 2368.2 | T2: =R2/S2 -> 1.6744152 | U2: =A2 -> 44865
A3: 44866 | B3: 3004.87 | C3: 103.35 | O3: 16.95 | Q3: 221.94 | R3: =SUM(B3:Q3) -> 3347.11 | S3: 5955.3 | T3: =R3/S3 -> 0.56203886 | U3: =A3 -> 44866
A4: 44867 | B4: 1001.9 | C4: 52.88 | E4: 240 | H4: 49.5 | P4: 100 | R4: =SUM(B4:Q4) -> 1444.28 | S4: =6755+369 -> 7124 | T4: =R4/S4 -> 0.20273442 | U4: =A4 -> 44867
A5: 44868 | B5: 1773.17 | C5: 422.3 | G5: 126.72 | R5: =SUM(B5:Q5) -> 2322.19 | S5: 8641.3 | T5: =R5/S5 -> 0.26873156 | U5: =A5 -> 44868
A6: 44869 | B6: 982.6 | G6: 516.9 | H6: 142.5 | P6: 100 | R6: =SUM(B6:Q6) -> 1742 | S6: 13867 | T6: =R6/S6 -> 0.12562198 | U6: =A6 -> 44869
A7: 44870 | B7: 2056.02 | C7: 326.95 | D7: 800 | H7: 33 | M7: 800 | R7: =SUM(B7:Q7) -> 4015.97 | S7: 15821.01 | T7: =R7/S7 -> 0.25383778 | U7: =A7 -> 44870
A8: 44871 | B8: N/A | C8: N/A | D8: N/A | E8: N/A | G8: N/A | H8: N/A | I8: N/A | J8: N/A | K8: N/A | L8: N/A | M8: N/A | N8: N/A | O8: N/A | P8: N/A | Q8: N/A | R8: 0 | S8: 9909.2 | T8: =R8/S8 -> 0 | U8: =A8 -> 44871
A10: Actuals | B10: 10564.26 | C10: 1664.25 | D10: 679 | E10: 290 | F10: 132.97 | G10: 1169.87 | H10: 225 | J10: 1460.63 | K10: 180 | M10: 828.33 | P10: 616.28 | Q10: 221.94
A11: Difference | B11: =sum(B2:B8)-B10 -> -515.23 | C11: =sum(C2:C8)-C10 -> -443.06 | D11: =sum(D2:D8)-D10 -> 121 | E11: =sum(E2:E8)-E10 -> -50 | F11: =sum(F2:F8)-F10 -> -132.97 | G11: =sum(G2:G8)-G10 -> -146.25 | H11: =sum(H2:H8)-H10 -> 0 | I11: =sum(I2:I8)-I10 -> 0 | ... P11: =sum(P2:P8)-P10 -> -316.28 | Q11: =Q10-0 -> 221.94 | R11: =R10-0 -> 0
M12: Estimate based on 6-week avg
C13: 383.47 | D13: $197 in oysterd carried into this week | F13: 126.72 - Bronzini on 11/3
A14: Budget | B14: 12000 | C14: 103.35 | G14: Carried $380 in scallops + $272 of smoked trout | P14: Missing sunflowers, tax, and delivery fee
A15: Total Weekly Spend | B15: =SUM(B2:Q8) -> 16836.9 | C15: 133.38 | D15: Beeef knuckle bones -- Kaysen event + $5 fuel surcharge
A16: Remaing Spend | B16: =SUM(B14-B15) -> -4836.9 | C16: 722.1 | D16: 195 clams kaysen, $295 in oysters. Some for SCSC?
A18: Weekly Food Revenue | B18: =SUM(S2:S8) -> 63686.01 | C18: 321.95
A19: Weekly Cost % | B19: =B15/B18 -> 0.2643736
A22: End of week status | H22: Scallops
A23: list items over $100 | H23: Date delivered | I23: Weight billed (lbs) | J23: Weight received (lbs)
A24: Items carrying over | B24: Amount | C24: Items discarded | D24: Amount | H24: 44869 | I24: 4# | J24: 4#
A25: Chicken Breasts | B25: 208.5 | I25: 8#
A26: 16# short Ribs | B26: 255.84
A27: White Chocolate | B27: 104.55
I32: Total left at EOW

Sheet Roister (117-1113)
B1: CW | C1: Fortune | D1: Closed Loop | E1: A1 Firewood | F1: Wabash | G1: Superior | H1: Aya | I1: Rocker Bros | J1: D'artagnan | K1: Four Star | L1: Regalis | M1: Cornille | N1: Truffles | O1: Rare Tea Cellar | P1: Steve's | Q1: Turano | R1: Daily Spend | S1: Daily Revenue | T1: Daily Cost %
A2: 44872 | B2: 2133.64 | C2: 1221.35 | E2: 190 | F2: 157.72 | J2: 255.84 | K2: 180 | P2: 100 | R2: =SUM(B2:Q2) -> 4238.55 | S2: 4604.4 | T2: =R2/S2 -> 0.92054339 | U2: =A2 -> 44872
A3: 44873 | B3: 1813.64 | C3: 781.22 | G3: 232 | J3: 607.94 | O3: 80 | R3: =SUM(B3:Q3) -> 3514.8 | S3: 5745 | T3: =R3/S3 -> 0.61180157 | U3: =A3 -> 44873
A4: 44874 | B4: 679.96 | C4: 29 | E4: 390 | F4: 516.9 | H4: 49.5 | O4: 19 | P4: 100 | Q4: 221.78 | R4: =SUM(B4:Q4) -> 2006.14 | S4: 8323 | T4: =R4/S4 -> 0.24103568 | U4: =A4 -> 44874
A5: 44875 | B5: 1879.41 | R5: =SUM(B5:Q5) -> 1879.41 | S5: 7674.4 | T5: =R5/S5 -> 0.24489341 | U5: =A5 -> 44875
